[2024-11-14 06:26:56,634] ERROR [django.security.DisallowedHost:124] Invalid HTTP_HOST header: '0.0.0.0'. You may need to add '0.0.0.0' to ALLOWED_HOSTS.
Traceback (most recent call last):
  File "/home/esteban/boostIn/envboostin/lib/python3.12/site-packages/django/core/handlers/exception.py", line 55, in inner
    response = get_response(request)
               ^^^^^^^^^^^^^^^^^^^^^
  File "/home/esteban/boostIn/envboostin/lib/python3.12/site-packages/django/utils/deprecation.py", line 133, in __call__
    response = self.process_request(request)
               ^^^^^^^^^^^^^^^^^^^^^^^^^^^^^
  File "/home/esteban/boostIn/envboostin/lib/python3.12/site-packages/django/middleware/common.py", line 48, in process_request
    host = request.get_host()
           ^^^^^^^^^^^^^^^^^^
  File "/home/esteban/boostIn/envboostin/lib/python3.12/site-packages/django/http/request.py", line 151, in get_host
    raise DisallowedHost(msg)
django.core.exceptions.DisallowedHost: Invalid HTTP_HOST header: '0.0.0.0'. You may need to add '0.0.0.0' to ALLOWED_HOSTS.
[2024-11-14 15:33:00,096] ERROR [django.request:241] Internal Server Error: /campagnes/c/14
Traceback (most recent call last):
  File "/home/esteban/boostIn/envboostin/lib/python3.12/site-packages/django/core/handlers/exception.py", line 55, in inner
    response = get_response(request)
               ^^^^^^^^^^^^^^^^^^^^^
  File "/home/esteban/boostIn/envboostin/lib/python3.12/site-packages/django/core/handlers/base.py", line 197, in _get_response
    response = wrapped_callback(request, *callback_args, **callback_kwargs)
               ^^^^^^^^^^^^^^^^^^^^^^^^^^^^^^^^^^^^^^^^^^^^^^^^^^^^^^^^^^^^
  File "/home/esteban/boostIn/envboostin/lib/python3.12/site-packages/django/contrib/auth/decorators.py", line 23, in _wrapper_view
    return view_func(request, *args, **kwargs)
           ^^^^^^^^^^^^^^^^^^^^^^^^^^^^^^^^^^^
  File "/home/esteban/boostIn/BoostIn/campagnes/views.py", line 194, in suivi_campagne
    pro_exe = datetime.fromisoformat(exe_dict["message"])
              ^^^^^^^^^^^^^^^^^^^^^^^^^^^^^^^^^^^^^^^^^^^
ValueError: Invalid isoformat string: 'erreur renvoyé'
[2024-11-14 15:33:50,377] ERROR [django.request:241] Internal Server Error: /campagnes/c/14
Traceback (most recent call last):
  File "/home/esteban/boostIn/envboostin/lib/python3.12/site-packages/django/core/handlers/exception.py", line 55, in inner
    response = get_response(request)
               ^^^^^^^^^^^^^^^^^^^^^
  File "/home/esteban/boostIn/envboostin/lib/python3.12/site-packages/django/core/handlers/base.py", line 197, in _get_response
    response = wrapped_callback(request, *callback_args, **callback_kwargs)
               ^^^^^^^^^^^^^^^^^^^^^^^^^^^^^^^^^^^^^^^^^^^^^^^^^^^^^^^^^^^^
  File "/home/esteban/boostIn/envboostin/lib/python3.12/site-packages/django/contrib/auth/decorators.py", line 23, in _wrapper_view
    return view_func(request, *args, **kwargs)
           ^^^^^^^^^^^^^^^^^^^^^^^^^^^^^^^^^^^
  File "/home/esteban/boostIn/BoostIn/campagnes/views.py", line 194, in suivi_campagne
    pro_exe = datetime.fromisoformat(exe_dict["message"])
              ^^^^^^^^^^^^^^^^^^^^^^^^^^^^^^^^^^^^^^^^^^^
ValueError: Invalid isoformat string: 'erreur renvoyé'
[2024-11-14 15:34:36,280] ERROR [django.request:241] Internal Server Error: /campagnes/c/14
Traceback (most recent call last):
  File "/home/esteban/boostIn/envboostin/lib/python3.12/site-packages/django/core/handlers/exception.py", line 55, in inner
    response = get_response(request)
               ^^^^^^^^^^^^^^^^^^^^^
  File "/home/esteban/boostIn/envboostin/lib/python3.12/site-packages/django/core/handlers/base.py", line 197, in _get_response
    response = wrapped_callback(request, *callback_args, **callback_kwargs)
               ^^^^^^^^^^^^^^^^^^^^^^^^^^^^^^^^^^^^^^^^^^^^^^^^^^^^^^^^^^^^
  File "/home/esteban/boostIn/envboostin/lib/python3.12/site-packages/django/contrib/auth/decorators.py", line 23, in _wrapper_view
    return view_func(request, *args, **kwargs)
           ^^^^^^^^^^^^^^^^^^^^^^^^^^^^^^^^^^^
  File "/home/esteban/boostIn/BoostIn/campagnes/views.py", line 194, in suivi_campagne
    pro_exe = datetime.fromisoformat(exe_dict["message"])
              ^^^^^^^^^^^^^^^^^^^^^^^^^^^^^^^^^^^^^^^^^^^
ValueError: Invalid isoformat string: 'erreur renvoyé'
[2024-11-14 15:36:58,358] ERROR [django.request:241] Internal Server Error: /campagnes/c/14
Traceback (most recent call last):
  File "/home/esteban/boostIn/envboostin/lib/python3.12/site-packages/django/core/handlers/exception.py", line 55, in inner
    response = get_response(request)
               ^^^^^^^^^^^^^^^^^^^^^
  File "/home/esteban/boostIn/envboostin/lib/python3.12/site-packages/django/core/handlers/base.py", line 197, in _get_response
    response = wrapped_callback(request, *callback_args, **callback_kwargs)
               ^^^^^^^^^^^^^^^^^^^^^^^^^^^^^^^^^^^^^^^^^^^^^^^^^^^^^^^^^^^^
  File "/home/esteban/boostIn/envboostin/lib/python3.12/site-packages/django/contrib/auth/decorators.py", line 23, in _wrapper_view
    return view_func(request, *args, **kwargs)
           ^^^^^^^^^^^^^^^^^^^^^^^^^^^^^^^^^^^
  File "/home/esteban/boostIn/BoostIn/campagnes/views.py", line 194, in suivi_campagne
    pro_exe = datetime.fromisoformat(exe_dict["message"])
              ^^^^^^^^^^^^^^^^^^^^^^^^^^^^^^^^^^^^^^^^^^^
ValueError: Invalid isoformat string: 'erreur renvoyé'
[2024-11-15 11:13:22,868] ERROR [django.request:241] Internal Server Error: /campagnes/c/14
Traceback (most recent call last):
  File "/home/esteban/boostIn/envboostin/lib/python3.12/site-packages/django/core/handlers/exception.py", line 55, in inner
    response = get_response(request)
               ^^^^^^^^^^^^^^^^^^^^^
  File "/home/esteban/boostIn/envboostin/lib/python3.12/site-packages/django/core/handlers/base.py", line 197, in _get_response
    response = wrapped_callback(request, *callback_args, **callback_kwargs)
               ^^^^^^^^^^^^^^^^^^^^^^^^^^^^^^^^^^^^^^^^^^^^^^^^^^^^^^^^^^^^
  File "/home/esteban/boostIn/envboostin/lib/python3.12/site-packages/django/contrib/auth/decorators.py", line 23, in _wrapper_view
    return view_func(request, *args, **kwargs)
           ^^^^^^^^^^^^^^^^^^^^^^^^^^^^^^^^^^^
  File "/home/esteban/boostIn/BoostIn/campagnes/views.py", line 194, in suivi_campagne
    pro_exe = datetime.fromisoformat(exe_dict["message"])
              ^^^^^^^^^^^^^^^^^^^^^^^^^^^^^^^^^^^^^^^^^^^
ValueError: Invalid isoformat string: 'erreur renvoyé'
[2024-11-18 01:21:34,659] ERROR [django.request:241] Internal Server Error: /campagnes/c/13
Traceback (most recent call last):
  File "/home/esteban/boostIn/envboostin/lib/python3.12/site-packages/django/core/handlers/exception.py", line 55, in inner
    response = get_response(request)
               ^^^^^^^^^^^^^^^^^^^^^
  File "/home/esteban/boostIn/envboostin/lib/python3.12/site-packages/django/core/handlers/base.py", line 197, in _get_response
    response = wrapped_callback(request, *callback_args, **callback_kwargs)
               ^^^^^^^^^^^^^^^^^^^^^^^^^^^^^^^^^^^^^^^^^^^^^^^^^^^^^^^^^^^^
  File "/home/esteban/boostIn/envboostin/lib/python3.12/site-packages/django/contrib/auth/decorators.py", line 23, in _wrapper_view
    return view_func(request, *args, **kwargs)
           ^^^^^^^^^^^^^^^^^^^^^^^^^^^^^^^^^^^
  File "/home/esteban/boostIn/BoostIn/campagnes/views.py", line 194, in suivi_campagne
    pro_exe = datetime.fromisoformat(exe_dict["message"])
              ^^^^^^^^^^^^^^^^^^^^^^^^^^^^^^^^^^^^^^^^^^^
ValueError: Invalid isoformat string: 'erreur renvoyé'
[2024-11-18 07:42:40,006] ERROR [django.security.DisallowedHost:124] Invalid HTTP_HOST header: '0.0.0.0'. You may need to add '0.0.0.0' to ALLOWED_HOSTS.
Traceback (most recent call last):
  File "/home/esteban/boostIn/envboostin/lib/python3.12/site-packages/django/core/handlers/exception.py", line 55, in inner
    response = get_response(request)
               ^^^^^^^^^^^^^^^^^^^^^
  File "/home/esteban/boostIn/envboostin/lib/python3.12/site-packages/django/utils/deprecation.py", line 133, in __call__
    response = self.process_request(request)
               ^^^^^^^^^^^^^^^^^^^^^^^^^^^^^
  File "/home/esteban/boostIn/envboostin/lib/python3.12/site-packages/django/middleware/common.py", line 48, in process_request
    host = request.get_host()
           ^^^^^^^^^^^^^^^^^^
  File "/home/esteban/boostIn/envboostin/lib/python3.12/site-packages/django/http/request.py", line 151, in get_host
    raise DisallowedHost(msg)
django.core.exceptions.DisallowedHost: Invalid HTTP_HOST header: '0.0.0.0'. You may need to add '0.0.0.0' to ALLOWED_HOSTS.
[2024-11-18 10:08:26,841] ERROR [django.security.DisallowedHost:124] Invalid HTTP_HOST header: '0.0.0.0'. You may need to add '0.0.0.0' to ALLOWED_HOSTS.
Traceback (most recent call last):
  File "/home/esteban/boostIn/envboostin/lib/python3.12/site-packages/django/core/handlers/exception.py", line 55, in inner
    response = get_response(request)
               ^^^^^^^^^^^^^^^^^^^^^
  File "/home/esteban/boostIn/envboostin/lib/python3.12/site-packages/django/utils/deprecation.py", line 133, in __call__
    response = self.process_request(request)
               ^^^^^^^^^^^^^^^^^^^^^^^^^^^^^
  File "/home/esteban/boostIn/envboostin/lib/python3.12/site-packages/django/middleware/common.py", line 48, in process_request
    host = request.get_host()
           ^^^^^^^^^^^^^^^^^^
  File "/home/esteban/boostIn/envboostin/lib/python3.12/site-packages/django/http/request.py", line 151, in get_host
    raise DisallowedHost(msg)
django.core.exceptions.DisallowedHost: Invalid HTTP_HOST header: '0.0.0.0'. You may need to add '0.0.0.0' to ALLOWED_HOSTS.
[2024-11-18 14:26:40,451] ERROR [django.request:241] Internal Server Error: /campagnes/c/13
Traceback (most recent call last):
  File "/home/esteban/boostIn/envboostin/lib/python3.12/site-packages/django/core/handlers/exception.py", line 55, in inner
    response = get_response(request)
               ^^^^^^^^^^^^^^^^^^^^^
  File "/home/esteban/boostIn/envboostin/lib/python3.12/site-packages/django/core/handlers/base.py", line 197, in _get_response
    response = wrapped_callback(request, *callback_args, **callback_kwargs)
               ^^^^^^^^^^^^^^^^^^^^^^^^^^^^^^^^^^^^^^^^^^^^^^^^^^^^^^^^^^^^
  File "/home/esteban/boostIn/envboostin/lib/python3.12/site-packages/django/contrib/auth/decorators.py", line 23, in _wrapper_view
    return view_func(request, *args, **kwargs)
           ^^^^^^^^^^^^^^^^^^^^^^^^^^^^^^^^^^^
  File "/home/esteban/boostIn/BoostIn/campagnes/views.py", line 194, in suivi_campagne
    pro_exe = datetime.fromisoformat(exe_dict["message"])
              ^^^^^^^^^^^^^^^^^^^^^^^^^^^^^^^^^^^^^^^^^^^
ValueError: Invalid isoformat string: 'erreur renvoyé'
[2024-11-19 09:47:56,268] ERROR [django.request:241] Internal Server Error: /campagnes/c/13
Traceback (most recent call last):
  File "/home/esteban/boostIn/envboostin/lib/python3.12/site-packages/django/core/handlers/exception.py", line 55, in inner
    response = get_response(request)
               ^^^^^^^^^^^^^^^^^^^^^
  File "/home/esteban/boostIn/envboostin/lib/python3.12/site-packages/django/core/handlers/base.py", line 197, in _get_response
    response = wrapped_callback(request, *callback_args, **callback_kwargs)
               ^^^^^^^^^^^^^^^^^^^^^^^^^^^^^^^^^^^^^^^^^^^^^^^^^^^^^^^^^^^^
  File "/home/esteban/boostIn/envboostin/lib/python3.12/site-packages/django/contrib/auth/decorators.py", line 23, in _wrapper_view
    return view_func(request, *args, **kwargs)
           ^^^^^^^^^^^^^^^^^^^^^^^^^^^^^^^^^^^
  File "/home/esteban/boostIn/BoostIn/campagnes/views.py", line 196, in suivi_campagne
    pro_exe = datetime.fromisoformat(exe_dict["message"])
              ^^^^^^^^^^^^^^^^^^^^^^^^^^^^^^^^^^^^^^^^^^^
ValueError: Invalid isoformat string: 'erreur renvoyé'
[2024-11-19 11:13:32,405] ERROR [django.request:241] Internal Server Error: /campagnes/c/13
Traceback (most recent call last):
  File "/home/esteban/boostIn/envboostin/lib/python3.12/site-packages/django/core/handlers/exception.py", line 55, in inner
    response = get_response(request)
               ^^^^^^^^^^^^^^^^^^^^^
  File "/home/esteban/boostIn/envboostin/lib/python3.12/site-packages/django/core/handlers/base.py", line 197, in _get_response
    response = wrapped_callback(request, *callback_args, **callback_kwargs)
               ^^^^^^^^^^^^^^^^^^^^^^^^^^^^^^^^^^^^^^^^^^^^^^^^^^^^^^^^^^^^
  File "/home/esteban/boostIn/envboostin/lib/python3.12/site-packages/django/contrib/auth/decorators.py", line 23, in _wrapper_view
    return view_func(request, *args, **kwargs)
           ^^^^^^^^^^^^^^^^^^^^^^^^^^^^^^^^^^^
  File "/home/esteban/boostIn/BoostIn/campagnes/views.py", line 210, in suivi_campagne
    return render(request, 'campagnes/suivi.html', {'con' : con, 'campagne' : campagne, 'prospect' : prospect, 'stat_con' : nb_acc, 'stat_mes' : nb_mes, "error" : err, "pro" : pro_exe, 'date_creation' : date_creation})
           ^^^^^^^^^^^^^^^^^^^^^^^^^^^^^^^^^^^^^^^^^^^^^^^^^^^^^^^^^^^^^^^^^^^^^^^^^^^^^^^^^^^^^^^^^^^^^^^^^^^^^^^^^^^^^^^^^^^^^^^^^^^^^^^^^^^^^^^^^^^^^^^^^^^^^^^^^^^^^^^^^^^^^^^^^^^^^^^^^^^^^^^^^^^^^^^^^^^^^^^^^^^^^^^
  File "/home/esteban/boostIn/envboostin/lib/python3.12/site-packages/django/shortcuts.py", line 25, in render
    content = loader.render_to_string(template_name, context, request, using=using)
              ^^^^^^^^^^^^^^^^^^^^^^^^^^^^^^^^^^^^^^^^^^^^^^^^^^^^^^^^^^^^^^^^^^^^^
  File "/home/esteban/boostIn/envboostin/lib/python3.12/site-packages/django/template/loader.py", line 61, in render_to_string
    template = get_template(template_name, using=using)
               ^^^^^^^^^^^^^^^^^^^^^^^^^^^^^^^^^^^^^^^^
  File "/home/esteban/boostIn/envboostin/lib/python3.12/site-packages/django/template/loader.py", line 15, in get_template
    return engine.get_template(template_name)
           ^^^^^^^^^^^^^^^^^^^^^^^^^^^^^^^^^^
  File "/home/esteban/boostIn/envboostin/lib/python3.12/site-packages/django/template/backends/django.py", line 33, in get_template
    return Template(self.engine.get_template(template_name), self)
                    ^^^^^^^^^^^^^^^^^^^^^^^^^^^^^^^^^^^^^^^
  File "/home/esteban/boostIn/envboostin/lib/python3.12/site-packages/django/template/engine.py", line 177, in get_template
    template, origin = self.find_template(template_name)
                       ^^^^^^^^^^^^^^^^^^^^^^^^^^^^^^^^^
  File "/home/esteban/boostIn/envboostin/lib/python3.12/site-packages/django/template/engine.py", line 159, in find_template
    template = loader.get_template(name, skip=skip)
               ^^^^^^^^^^^^^^^^^^^^^^^^^^^^^^^^^^^^
  File "/home/esteban/boostIn/envboostin/lib/python3.12/site-packages/django/template/loaders/cached.py", line 57, in get_template
    template = super().get_template(template_name, skip)
               ^^^^^^^^^^^^^^^^^^^^^^^^^^^^^^^^^^^^^^^^^
  File "/home/esteban/boostIn/envboostin/lib/python3.12/site-packages/django/template/loaders/base.py", line 28, in get_template
    return Template(
           ^^^^^^^^^
  File "/home/esteban/boostIn/envboostin/lib/python3.12/site-packages/django/template/base.py", line 154, in __init__
    self.nodelist = self.compile_nodelist()
                    ^^^^^^^^^^^^^^^^^^^^^^^
  File "/home/esteban/boostIn/envboostin/lib/python3.12/site-packages/django/template/base.py", line 196, in compile_nodelist
    return parser.parse()
           ^^^^^^^^^^^^^^
  File "/home/esteban/boostIn/envboostin/lib/python3.12/site-packages/django/template/base.py", line 510, in parse
    raise self.error(token, e)
  File "/home/esteban/boostIn/envboostin/lib/python3.12/site-packages/django/template/base.py", line 508, in parse
    compiled_result = compile_func(self, token)
                      ^^^^^^^^^^^^^^^^^^^^^^^^^
  File "/home/esteban/boostIn/envboostin/lib/python3.12/site-packages/django/template/loader_tags.py", line 295, in do_extends
    nodelist = parser.parse()
               ^^^^^^^^^^^^^^
  File "/home/esteban/boostIn/envboostin/lib/python3.12/site-packages/django/template/base.py", line 510, in parse
    raise self.error(token, e)
  File "/home/esteban/boostIn/envboostin/lib/python3.12/site-packages/django/template/base.py", line 508, in parse
    compiled_result = compile_func(self, token)
                      ^^^^^^^^^^^^^^^^^^^^^^^^^
  File "/home/esteban/boostIn/envboostin/lib/python3.12/site-packages/django/template/loader_tags.py", line 234, in do_block
    nodelist = parser.parse(("endblock",))
               ^^^^^^^^^^^^^^^^^^^^^^^^^^^
  File "/home/esteban/boostIn/envboostin/lib/python3.12/site-packages/django/template/base.py", line 510, in parse
    raise self.error(token, e)
  File "/home/esteban/boostIn/envboostin/lib/python3.12/site-packages/django/template/base.py", line 508, in parse
    compiled_result = compile_func(self, token)
                      ^^^^^^^^^^^^^^^^^^^^^^^^^
  File "/home/esteban/boostIn/envboostin/lib/python3.12/site-packages/django/template/defaulttags.py", line 861, in do_for
    nodelist_loop = parser.parse(
                    ^^^^^^^^^^^^^
  File "/home/esteban/boostIn/envboostin/lib/python3.12/site-packages/django/template/base.py", line 481, in parse
    raise self.error(token, e)
  File "/home/esteban/boostIn/envboostin/lib/python3.12/site-packages/django/template/base.py", line 479, in parse
    filter_expression = self.compile_filter(token.contents)
                        ^^^^^^^^^^^^^^^^^^^^^^^^^^^^^^^^^^^
  File "/home/esteban/boostIn/envboostin/lib/python3.12/site-packages/django/template/base.py", line 597, in compile_filter
    return FilterExpression(token, self)
           ^^^^^^^^^^^^^^^^^^^^^^^^^^^^^
  File "/home/esteban/boostIn/envboostin/lib/python3.12/site-packages/django/template/base.py", line 698, in __init__
    raise TemplateSyntaxError(
django.template.exceptions.TemplateSyntaxError: Could not parse the remainder: '[0]' from 'err[0]'
[2024-11-19 11:45:11,102] ERROR [django.request:241] Internal Server Error: /campagnes/stat
Traceback (most recent call last):
  File "/home/esteban/boostIn/envboostin/lib/python3.12/site-packages/django/core/handlers/exception.py", line 55, in inner
    response = get_response(request)
               ^^^^^^^^^^^^^^^^^^^^^
  File "/home/esteban/boostIn/envboostin/lib/python3.12/site-packages/django/core/handlers/base.py", line 197, in _get_response
    response = wrapped_callback(request, *callback_args, **callback_kwargs)
               ^^^^^^^^^^^^^^^^^^^^^^^^^^^^^^^^^^^^^^^^^^^^^^^^^^^^^^^^^^^^
  File "/home/esteban/boostIn/envboostin/lib/python3.12/site-packages/django/contrib/auth/decorators.py", line 23, in _wrapper_view
    return view_func(request, *args, **kwargs)
           ^^^^^^^^^^^^^^^^^^^^^^^^^^^^^^^^^^^
  File "/home/esteban/boostIn/BoostIn/campagnes/views.py", line 481, in get_stat_by_day
    con_id = con[con.index('/')+1:]
                 ^^^^^^^^^^^^^^
ValueError: substring not found
[2024-11-19 11:46:39,418] ERROR [django.request:241] Internal Server Error: /campagnes/d/erreur/2/13
Traceback (most recent call last):
  File "/home/esteban/boostIn/envboostin/lib/python3.12/site-packages/django/core/handlers/exception.py", line 55, in inner
    response = get_response(request)
               ^^^^^^^^^^^^^^^^^^^^^
  File "/home/esteban/boostIn/envboostin/lib/python3.12/site-packages/django/core/handlers/base.py", line 204, in _get_response
    self.check_response(response, callback)
  File "/home/esteban/boostIn/envboostin/lib/python3.12/site-packages/django/core/handlers/base.py", line 332, in check_response
    raise ValueError(
ValueError: The view campagnes.views.delete_error didn't return an HttpResponse object. It returned None instead.
[2024-11-19 11:47:38,222] ERROR [django.request:241] Internal Server Error: /campagnes/d/erreur/2/13
Traceback (most recent call last):
  File "/home/esteban/boostIn/envboostin/lib/python3.12/site-packages/django/core/handlers/exception.py", line 55, in inner
    response = get_response(request)
               ^^^^^^^^^^^^^^^^^^^^^
  File "/home/esteban/boostIn/envboostin/lib/python3.12/site-packages/django/core/handlers/base.py", line 197, in _get_response
    response = wrapped_callback(request, *callback_args, **callback_kwargs)
               ^^^^^^^^^^^^^^^^^^^^^^^^^^^^^^^^^^^^^^^^^^^^^^^^^^^^^^^^^^^^
  File "/home/esteban/boostIn/envboostin/lib/python3.12/site-packages/django/contrib/auth/decorators.py", line 23, in _wrapper_view
    return view_func(request, *args, **kwargs)
           ^^^^^^^^^^^^^^^^^^^^^^^^^^^^^^^^^^^
  File "/home/esteban/boostIn/BoostIn/campagnes/views.py", line 222, in delete_error
    return redirect('suivi_campagne', con.id)
                                      ^^^
UnboundLocalError: cannot access local variable 'con' where it is not associated with a value
[2024-11-19 14:47:59,021] ERROR [django.security.DisallowedHost:124] Invalid HTTP_HOST header: '0.0.0.0'. You may need to add '0.0.0.0' to ALLOWED_HOSTS.
Traceback (most recent call last):
  File "/home/esteban/boostIn/envboostin/lib/python3.12/site-packages/django/core/handlers/exception.py", line 55, in inner
    response = get_response(request)
               ^^^^^^^^^^^^^^^^^^^^^
  File "/home/esteban/boostIn/envboostin/lib/python3.12/site-packages/django/utils/deprecation.py", line 133, in __call__
    response = self.process_request(request)
               ^^^^^^^^^^^^^^^^^^^^^^^^^^^^^
  File "/home/esteban/boostIn/envboostin/lib/python3.12/site-packages/django/middleware/common.py", line 48, in process_request
    host = request.get_host()
           ^^^^^^^^^^^^^^^^^^
  File "/home/esteban/boostIn/envboostin/lib/python3.12/site-packages/django/http/request.py", line 151, in get_host
    raise DisallowedHost(msg)
django.core.exceptions.DisallowedHost: Invalid HTTP_HOST header: '0.0.0.0'. You may need to add '0.0.0.0' to ALLOWED_HOSTS.
[2024-11-19 14:57:56,045] ERROR [django.request:241] Internal Server Error: /campagnes/test_sse/
Traceback (most recent call last):
  File "/home/esteban/boostIn/envboostin/lib/python3.12/site-packages/django/core/handlers/exception.py", line 55, in inner
    response = get_response(request)
               ^^^^^^^^^^^^^^^^^^^^^
  File "/home/esteban/boostIn/envboostin/lib/python3.12/site-packages/django/core/handlers/base.py", line 204, in _get_response
    self.check_response(response, callback)
  File "/home/esteban/boostIn/envboostin/lib/python3.12/site-packages/django/core/handlers/base.py", line 332, in check_response
    raise ValueError(
ValueError: The view campagnes.views.vue_sse didn't return an HttpResponse object. It returned None instead.
